{"Modified":"2022-04-13T13:45:00","Published":"2022-04-04T20:15:00","access":{"authentication":"NONE","complexity":"LOW","vector":"NETWORK"},"assigner":"ics-cert@hq.dhs.gov","capec":[],"cvss":5,"cvss-time":"2022-04-13T13:45:00","cvss-vector":"AV:N/AC:L/Au:N/C:N/I:N/A:P","cwe":"NVD-CWE-Other","id":"CVE-2021-33010","impact":{"availability":"PARTIAL","confidentiality":"NONE","integrity":"NONE"},"last-modified":"2022-04-13T13:45:00","references":["https://www.aveva.com/content/dam/aveva/documents/support/cyber-security-updates/SecurityBulletin_AVEVA-2021-002.pdf","https://www.cisa.gov/uscert/ics/advisories/icsa-21-180-05"],"summary":"An exception is thrown from a function in AVEVA System Platform versions 2017 through 2020 R2 P01, but it is not caught, which may cause a denial-of-service condition.","vulnerable_configuration":[{"id":"cpe:2.3:a:aveva:system_platform:*:*:*:*:*:*:*:*","title":"cpe:2.3:a:aveva:system_platform:*:*:*:*:*:*:*:*"},{"id":"cpe:2.3:a:aveva:system_platform:2020:-:*:*:*:*:*:*","title":"cpe:2.3:a:aveva:system_platform:2020:-:*:*:*:*:*:*"},{"id":"cpe:2.3:a:aveva:system_platform:2020:r2:*:*:*:*:*:*","title":"cpe:2.3:a:aveva:system_platform:2020:r2:*:*:*:*:*:*"},{"id":"cpe:2.3:a:aveva:system_platform:2020:r2_p01:*:*:*:*:*:*","title":"cpe:2.3:a:aveva:system_platform:2020:r2_p01:*:*:*:*:*:*"}],"vulnerable_configuration_cpe_2_2":[],"vulnerable_product":["cpe:2.3:a:aveva:system_platform:*:*:*:*:*:*:*:*","cpe:2.3:a:aveva:system_platform:2020:-:*:*:*:*:*:*","cpe:2.3:a:aveva:system_platform:2020:r2:*:*:*:*:*:*","cpe:2.3:a:aveva:system_platform:2020:r2_p01:*:*:*:*:*:*"]}