{"Modified":"2023-07-07T12:50:00","Published":"2023-07-06T21:15:00","access":{},"assigner":"cve@mitre.org","cvss":null,"cwe":"Unknown","id":"CVE-2023-29824","impact":{},"last-modified":"2023-07-07T12:50:00","references":["https://github.com/scipy/scipy/issues/14713","http://www.square16.org/achievement/cve-2023-29824/","https://github.com/scipy/scipy/pull/15013"],"summary":"A use-after-free issue was discovered in Py_FindObjects() function in SciPy versions prior to 1.8.0.","vulnerable_configuration":[],"vulnerable_configuration_cpe_2_2":[],"vulnerable_product":[]}