{"Modified":"2017-08-29T01:33:00","Published":"2013-06-19T13:39:00","access":{"authentication":"NONE","complexity":"MEDIUM","vector":"NETWORK"},"assigner":"cve@mitre.org","capec":[],"cvss":4.3,"cvss-time":"2017-08-29T01:33:00","cvss-vector":"AV:N/AC:M/Au:N/C:N/I:N/A:P","cwe":"NVD-CWE-noinfo","id":"CVE-2013-0484","impact":{"availability":"PARTIAL","confidentiality":"NONE","integrity":"NONE"},"last-modified":"2017-08-29T01:33:00","references":["http://www-01.ibm.com/support/docview.wss?uid=swg21637655","https://exchange.xforce.ibmcloud.com/vulnerabilities/81612"],"refmap":{"confirm":["http://www-01.ibm.com/support/docview.wss?uid=swg21637655"],"xf":["tm1-undocumented-api(81612)"]},"summary":"The server process in IBM Cognos TM1 10.1.x before 10.1.1 FP1 allows remote attackers to cause a denial of service (daemon crash) via an undocumented API call that triggers the transmission of unexpected data.","vulnerable_configuration":[{"id":"cpe:2.3:a:ibm:cognos_tm1:10.1.0:*:*:*:*:*:*:*","title":"cpe:2.3:a:ibm:cognos_tm1:10.1.0:*:*:*:*:*:*:*"},{"id":"cpe:2.3:a:ibm:cognos_tm1:10.1.0.1:*:*:*:*:*:*:*","title":"cpe:2.3:a:ibm:cognos_tm1:10.1.0.1:*:*:*:*:*:*:*"},{"id":"cpe:2.3:a:ibm:cognos_tm1:10.1.1:*:*:*:*:*:*:*","title":"cpe:2.3:a:ibm:cognos_tm1:10.1.1:*:*:*:*:*:*:*"}],"vulnerable_configuration_cpe_2_2":[],"vulnerable_product":["cpe:2.3:a:ibm:cognos_tm1:10.1.0:*:*:*:*:*:*:*","cpe:2.3:a:ibm:cognos_tm1:10.1.0.1:*:*:*:*:*:*:*","cpe:2.3:a:ibm:cognos_tm1:10.1.1:*:*:*:*:*:*:*"]}