{"Modified":"2020-08-24T17:37:00","Published":"2019-12-05T01:15:00","access":{"authentication":"NONE","complexity":"LOW","vector":"NETWORK"},"assigner":"cve@mitre.org","capec":[],"cvss":7.8,"cvss-time":"2020-08-24T17:37:00","cvss-vector":"AV:N/AC:L/Au:N/C:N/I:N/A:C","cwe":"CWE-835","id":"CVE-2019-19588","impact":{"availability":"COMPLETE","confidentiality":"NONE","integrity":"NONE"},"last-modified":"2020-08-24T17:37:00","references":["https://github.com/kvesteri/validators/issues/86"],"refmap":{"misc":["https://github.com/kvesteri/validators/issues/86"]},"summary":"The validators package 0.12.2 through 0.12.5 for Python enters an infinite loop when validators.domain is called with a crafted domain string. This is fixed in 0.12.6.","vulnerable_configuration":[{"id":"cpe:2.3:a:validators_project:validators:0.12.2:*:*:*:*:python:*:*","title":"cpe:2.3:a:validators_project:validators:0.12.2:*:*:*:*:python:*:*"},{"id":"cpe:2.3:a:validators_project:validators:0.12.3:*:*:*:*:python:*:*","title":"cpe:2.3:a:validators_project:validators:0.12.3:*:*:*:*:python:*:*"},{"id":"cpe:2.3:a:validators_project:validators:0.12.4:*:*:*:*:python:*:*","title":"cpe:2.3:a:validators_project:validators:0.12.4:*:*:*:*:python:*:*"},{"id":"cpe:2.3:a:validators_project:validators:0.12.5:*:*:*:*:python:*:*","title":"cpe:2.3:a:validators_project:validators:0.12.5:*:*:*:*:python:*:*"}],"vulnerable_configuration_cpe_2_2":[],"vulnerable_product":["cpe:2.3:a:validators_project:validators:0.12.2:*:*:*:*:python:*:*","cpe:2.3:a:validators_project:validators:0.12.3:*:*:*:*:python:*:*","cpe:2.3:a:validators_project:validators:0.12.4:*:*:*:*:python:*:*","cpe:2.3:a:validators_project:validators:0.12.5:*:*:*:*:python:*:*"]}